Workbook
Name 会場設営費: 注意事項!$B$26:$B$31
Name 企画・演出費: 注意事項!$B$32:$B$37
Name 広報費: #REF!
Name 講師関係費: 注意事項!$B$49:$B$54
Name 雑費: #REF!
Name 参加記念品費: #REF!
Name 資料作成費: 注意事項!#REF!
Name 渉外費: #REF!
Name 通信費: #REF!
Name 保険料: #REF!
Name 報告書作成費: #REF!
Name 本部団関係費: 注意事項!$B$38:$B$48
Name 予備費: #REF!
Name 旅費交通費: 注意事項!$B$74:$B$76

Sheet 注意事項
A1: 2025年度 財政予算様式フォ-ム
A3: 事業会計関連様式
A4: 様式1 | B4: 注意事項
A5: 様式2 | B5: 収支予算書 | C5: ※必ず別記「勘定科目」を遵守して下さい。 ※予備費は全ての事業につき、事業予算の3%以内として下さい。
A6: 様式3 | B6: 収益費用明細書 | C6: ※見積№と一致しているか確認して、見積書にリンクさせて下さい。 ※摘要は何をいくつ使うのか具体的に記入。（数量の根拠が必要）
A7: 様式4 | B7: 見積（請求）企業一覧表 | C7: 見積NO.から見積書にリンクさせてください。
A9: 2025年度 勘定科目一覧
A10: 【収益の部】
A11: 科目 | B11: 細 目 | C11: 勘定科目の内容説明 | D11: 消費税等課税区分
A12: 登録料収益 | C12: 事業参加者の会費 （注１ | D12: 課税収益
A13: 寄付金収益 | C13: 企業・団体・個人からの事業に対する寄付金 | D13: 特定収益
A14: 補助金 | B14: 国庫補助金 | C14: 国から事業に対する補助金 | D14: 特定収益
B15: 地方公共団体補助金 | C15: 地方公共団体から事業に対する補助金 | D15: 特定収益
B16: 民間補助金 | C16: 団体から事業に対する補助金 | D16: 特定収益
A17: 助成金 | B17: 国庫助成金 | C17: 国より支出される事業委託金 | D17: 特定収益（注２
B18: 地方公共団体助成金 | C18: 地方公共団体より支出される事業委託金 | D18: 特定収益（注２
B19: 民間助成金 | C19: 団体より支出される事業委託金 | D19: 特定収益（注２
A20: 広告料収益 | C20: 新聞、プログラム等に掲載する広告協賛金 | D20: 課税収益
A21: 販売収益 | C21: 物品等の販売による収入 | D21: 課税収益
A22: 事業繰入金 | C22: 一般会計の事業費からの繰入金 | D22: その他収益
A23: 雑収益 | C23: 預金利息 | D23: 非課税収益（注３
A24: 【費用の部】
A25: 科目 | B25: 細 目 | C25: 勘定科目の内容説明 | D25: 消費税等課税区分
A26: 会場設営費 | B26: 会場費 | C26: 事業、大会等の会場使用料 | D26: 課税支出
B27: 設営費 | C27: 会場の舞台装置及び関連設備の費用 | D27: 課税支出
B28: レンタル料 | C28: 機材等のレンタル料 | D28: 課税支出
B29: 運送費 | C29: 機材等の運搬料 | D29: 課税支出
B30: 人件費 | C30: 会場設営に関わる業者人件費 | D30: 非課税その他 （注５
B31: 食事代 | C31: 会場設営に関わるボランティア等の食事代 | D31: 課税支出
A32: 企画・演出費 | B32: 企画費 | C32: 事業、大会等の企画費 | D32: 課税支出
B33: 演出費 | C33: 事業、大会等の演出費 | D33: 課税支出
B34: 人件費 | C34: アルバイト、通訳、アドバイザ-等の人件費 | D34: 課税支出（注５
B35: 旅費交通費 | C35: 企画・演出に伴う旅費交通費 | D35: 課税支出
B36: 消耗品費 | C36: 企画・演出に伴う消耗品費 | D36: 課税支出
B37: 食事代 | C37: 企画・演出に伴うボランティア等の食事代 | D37: 課税支出（注 １０
A38: 本部団関係費 | B38: 会場費 | C38: 本部団の会場使用料 | D38: 課税支出
B39: 設営費 | C39: 本部団の設営機材等の費用 | D39: 課税支出
B40: レンタル料 | C40: 本部団の機材等のレンタル料 | D40: 課税支出
B41: 運送費 | C41: 本部団機材の運搬費 | D41: 課税支出
B42: 人件費 | C42: 事務職員、医師・看護婦等の給与及び謝礼金 | D42: 非課税その他（注５
...

Sheet 収支予算書(様式2)
F1: [様式2]
A2: 事 業 計 画 収 支 予 算 書
B4: 事業名称：
F5: （単位 ： 円）
B6: 項 目 | C6: 予 算 額 | D6: 前年度予算額 | E6: 前年度決算額 | F6: 摘 要
B7: （収 益 の 部）
A8: 1 | B8: 登 録 料 収 益 | C8: =IFERROR(VLOOKUP(B8,'収益・費用明細書(様式3)'!$D$6:$G$15,4,FALSE),0) -> 0 | D8: 0 | E8: 0
A9: 2 | B9: 寄 付 金 収 益 | C9: =IFERROR(VLOOKUP(B9,'収益・費用明細書(様式3)'!$D$6:$G$15,4,FALSE),0) -> 0 | D9: 0 | E9: 0
A10: 3 | B10: 補 助 金 | C10: =IFERROR(VLOOKUP(B10,'収益・費用明細書(様式3)'!$D$6:$G$15,4,FALSE),0) -> 0 | D10: 0 | E10: 0
A11: 4 | B11: 助 成 金 | C11: =IFERROR(VLOOKUP(B11,'収益・費用明細書(様式3)'!$D$6:$G$15,4,FALSE),0) -> 0 | D11: 0 | E11: 0
A12: 5 | B12: 広 告 料 収 益 | C12: =IFERROR(VLOOKUP(B12,'収益・費用明細書(様式3)'!$D$6:$G$15,4,FALSE),0) -> 0 | D12: 0 | E12: 0
A13: 6 | B13: 販 売 収 益 | C13: =IFERROR(VLOOKUP(B13,'収益・費用明細書(様式3)'!$D$6:$G$15,4,FALSE),0) -> 0 | D13: 0 | E13: 0
A14: 7 | B14: 事 業 繰 入 金 | C14: =IFERROR(VLOOKUP(B14,'収益・費用明細書(様式3)'!$D$6:$G$15,4,FALSE),0) -> 0 | D14: 0 | E14: 0
A15: 8 | B15: 雑 収 益 | C15: =IFERROR(VLOOKUP(B15,'収益・費用明細書(様式3)'!$D$6:$G$15,4,FALSE),0) -> 0 | D15: 0 | E15: 0
B16: 収益計 | C16: =SUM(C8:C15) -> 0 | D16: =SUM(D8:D15) -> 0 | E16: 0
B17: （費用の部）
A18: 1 | B18: 会場設営費 | C18: {=IFERROR(INDEX('収益・費用明細書(様式3)'!$D$1:$G$3000,MATCH('収支予算書(様式2)'!B18&" 小 計",'収益・費用明細書(様式3)'!$D$1:$D$3000&'収益・費用明細書(様式3)'!$F$1:$F$3000,0),4),0)} -> 0 | D18: 0 | E18: 0
A19: 2 | B19: 企画・演出費 | C19: {=IFERROR(INDEX('収益・費用明細書(様式3)'!$D$1:$G$3000,MATCH('収支予算書(様式2)'!B19&" 小 計",'収益・費用明細書(様式3)'!$D$1:$D$3000&'収益・費用明細書(様式3)'!$F$1:$F$3000,0),4),0)} -> 0 | D19: 0 | E19: 0
A20: 3 | B20: 本部団関係費 | C20: {=IFERROR(INDEX('収益・費用明細書(様式3)'!$D$1:$G$3000,MATCH('収支予算書(様式2)'!B20&" 小 計",'収益・費用明細書(様式3)'!$D$1:$D$3000&'収益・費用明細書(様式3)'!$F$1:$F$3000,0),4),0)} -> 0 | D20: 0 | E20: 0
A21: 4 | B21: 講師関係費 | C21: {=IFERROR(INDEX('収益・費用明細書(様式3)'!$D$1:$G$3000,MATCH('収支予算書(様式2)'!B21&" 小 計",'収益・費用明細書(様式3)'!$D$1:$D$3000&'収益・費用明細書(様式3)'!$F$1:$F$3000,0),4),0)} -> 0 | D21: 0 | E21: 0
A22: 5 | B22: 広報費 | C22: {=IFERROR(INDEX('収益・費用明細書(様式3)'!$D$1:$G$3000,MATCH('収支予算書(様式2)'!B22&" 小 計",'収益・費用明細書(様式3)'!$D$1:$D$3000&'収益・費用明細書(様式3)'!$F$1:$F$3000,0),4),0)} -> 0 | D22: 0 | E22: 0
A23: 6 | B23: 資料作成費 | C23: {=IFERROR(INDEX('収益・費用明細書(様式3)'!$D$1:$G$3000,MATCH('収支予算書(様式2)'!B23&" 小 計",'収益・費用明細書(様式3)'!$D$1:$D$3000&'収益・費用明細書(様式3)'!$F$1:$F$3000,0),4),0)} -> 0 | D23: 0 | E23: 0
A24: 7 | B24: 報告書作成費 | C24: {=IFERROR(INDEX('収益・費用明細書(様式3)'!$D$1:$G$3000,MATCH('収支予算書(様式2)'!B24&" 小 計",'収益・費用明細書(様式3)'!$D$1:$D$3000&'収益・費用明細書(様式3)'!$F$1:$F$3000,0),4),0)} -> 0 | D24: 0 | E24: 0
A25: 8 | B25: 渉外費 | C25: {=IFERROR(INDEX('収益・費用明細書(様式3)'!$D$1:$G$3000,MATCH('収支予算書(様式2)'!B25&" 小 計",'収益・費用明細書(様式3)'!$D$1:$D$3000&'収益・費用明細書(様式3)'!$F$1:$F$3000,0),4),0)} -> 0 | D25: 0 | E25: 0
A26: 9 | B26: 旅費交通費 | C26: {=IFERROR(INDEX('収益・費用明細書(様式3)'!$D$1:$G$3000,MATCH('収支予算書(様式2)'!B26&" 小 計",'収益・費用明細書(様式3)'!$D$1:$D$3000&'収益・費用明細書(様式3)'!$F$1:$F$3000,0),4),0)} -> 0 | D26: 0 | E26: 0
A27: 10 | B27: 参加記念品費 | C27: {=IFERROR(INDEX('収益・費用明細書(様式3)'!$D$1:$G$3000,MATCH('収支予算書(様式2)'!B27&" 小 計",'収益・費用明細書(様式3)'!$D$1:$D$3000&'収益・費用明細書(様式3)'!$F$1:$F$3000,0),4),0)} -> 0 | D27: 0 | E27: 0
A28: 11 | B28: 保険料 | C28: {=IFERROR(INDEX('収益・費用明細書(様式3)'!$D$1:$G$3000,MATCH('収支予算書(様式2)'!B28&" 小 計",'収益・費用明細書(様式3)'!$D$1:$D$3000&'収益・費用明細書(様式3)'!$F$1:$F$3000,0),4),0)} -> 0 | D28: 0 | E28: 0
A29: 12 | B29: 通信費 | C29: {=IFERROR(INDEX('収益・費用明細書(様式3)'!$D$1:$G$3000,MATCH('収支予算書(様式2)'!B29&" 小 計",'収益・費用明細書(様式3)'!$D$1:$D$3000&'収益・費用明細書(様式3)'!$F$1:$F$3000,0),4),0)} -> 0 | D29: 0 | E29: 0
A30: 13 | B30: 雑費 | C30: {=IFERROR(INDEX('収益・費用明細書(様式3)'!$D$1:$G$3000,MATCH('収支予算書(様式2)'!B30&" 小 計",'収益・費用明細書(様式3)'!$D$1:$D$3000&'収益・費用明細書(様式3)'!$F$1:$F$3000,0),4),0)} -> 0 | D30: 0 | E30: 0
A31: 14 | B31: 予備費 | C31: {=IFERROR(INDEX('収益・費用明細書(様式3)'!$D$1:$G$3000,MATCH('収支予算書(様式2)'!B31&" 小 計",'収益・費用明細書(様式3)'!$D$1:$D$3000&'収益・費用明細書(様式3)'!$F$1:$F$3000,0),4),0)} -> 0 | D31: 0 | E31: 0 | F31: =ROUNDDOWN(IFERROR(C31/C32, ""),4) -> 0
B32: 支出計 | C32: =SUM(C18:C31) -> 0 | D32: =SUM(D18:D31) -> 0 | E32: =SUM(E18:E31) -> 0
B33: 収支差額 | C33: =C16-C32 -> 0 | D33: =D16-D32 -> 0 | E33: =E16-E32 -> 0

Sheet 収益・費用明細書(様式3)
D1: [様式3]
B2: 事業名称：
A4: （ 収 益 明 細 書 ） | H4: （単位：円）
A5: 科 目 | E5: 摘 要 | G5: 金 額 | H5: No
A6: ( | B6: 1 | C6: ) | D6: =IF(B6="","括弧内に様式2の項目番号を入れてください",VLOOKUP(B6,'収支予算書(様式2)'!$A$8:$B$15,2,FALSE)) -> 登 録 料 収 益 | G6: 0
A7: ( | C7: ) | D7: =IF(B7="","括弧内に様式2の項目番号を入れてください",VLOOKUP(B7,'収支予算書(様式2)'!$A$8:$B$15,2,FALSE)) -> 括弧内に様式2の項目番号を入れてください | G7: 0
A8: ( | C8: ) | D8: =IF(B8="","括弧内に様式2の項目番号を入れてください",VLOOKUP(B8,'収支予算書(様式2)'!$A$8:$B$15,2,FALSE)) -> 括弧内に様式2の項目番号を入れてください | G8: 0
A9: ( | C9: ) | D9: =IF(B9="","括弧内に様式2の項目番号を入れてください",VLOOKUP(B9,'収支予算書(様式2)'!$A$8:$B$15,2,FALSE)) -> 括弧内に様式2の項目番号を入れてください | G9: 0
A10: 合 計 | G10: =SUM(G6:G9) -> 0
A14: （ 費 用 明 細 書 ） | H14: （単位：円）
A15: 科 目 | E15: 細 目 | F15: 摘 要 | G15: 金 額 | H15: No
A16: ( | B16: 1 | C16: ) | D16: =IF(B16="","括弧内に様式2の項目番号を入れてください",VLOOKUP(B16,'収支予算書(様式2)'!$A$18:$B$31,2,FALSE)) -> 会場設営費 | G16: 0
D17: =D16 -> 会場設営費 | G17: 0
D18: =D16 -> 会場設営費 | G18: 0
D19: =D16 -> 会場設営費 | F19: 小 計 | G19: =SUM(G16:G18) -> 0
A20: ( | C20: ) | D20: =IF(B20="","括弧内に様式2の項目番号を入れてください",VLOOKUP(B20,'収支予算書(様式2)'!$A$18:$B$31,2,FALSE)) -> 括弧内に様式2の項目番号を入れてください | G20: 0
D21: =D20 -> 括弧内に様式2の項目番号を入れてください | G21: 0
D22: =D20 -> 括弧内に様式2の項目番号を入れてください | G22: 0
D23: =D20 -> 括弧内に様式2の項目番号を入れてください | F23: 小 計 | G23: =SUM(G20:G22) -> 0
A24: ( | C24: ) | D24: =IF(B24="","括弧内に様式2の項目番号を入れてください",VLOOKUP(B24,'収支予算書(様式2)'!$A$18:$B$31,2,FALSE)) -> 括弧内に様式2の項目番号を入れてください | G24: 0
D25: =D24 -> 括弧内に様式2の項目番号を入れてください | G25: 0
D26: =D24 -> 括弧内に様式2の項目番号を入れてください | G26: 0
D27: =D24 -> 括弧内に様式2の項目番号を入れてください | F27: 小 計 | G27: =SUM(G24:G26) -> 0
A28: ( | C28: ) | D28: =IF(B28="","括弧内に様式2の項目番号を入れてください",VLOOKUP(B28,'収支予算書(様式2)'!$A$18:$B$31,2,FALSE)) -> 括弧内に様式2の項目番号を入れてください | G28: 0
D29: =D28 -> 括弧内に様式2の項目番号を入れてください | G29: 0
D30: =D28 -> 括弧内に様式2の項目番号を入れてください | G30: 0
D31: =D28 -> 括弧内に様式2の項目番号を入れてください | F31: 小 計 | G31: =SUM(G28:G30) -> 0
A32: ( | B32: 14 | C32: ) | D32: =IF(B32="","括弧内に様式2の項目番号を入れてください",VLOOKUP(B32,'収支予算書(様式2)'!$A$18:$B$31,2,FALSE)) -> 予備費 | F32: =ROUNDDOWN(IFERROR(G32/G34, ""),4) -> 0 | G32: 0
D33: =D32 -> 予備費 | F33: 小 計 | G33: =SUM(G32:G32) -> 0
F34: 合 計 | G34: =SUM(G33,G31,G27,G23,G19) -> 0

Sheet 見積企業一覧表(様式4)
F1: 〔様式4〕
A2: 見積企業一覧表
A3: （ 事業名称 ： ）
A5: 採 用 企 業
A6: =IF(A2="見積企業一覧表","見積№",IF(A2="請求企業一覧表","請求№","")) -> 見積№ | B6: 企 業 名 | C6: 支払内容（科目・細目） | D6: 金 額 | E6: 有効期限
D7: 0
D8: 0
D9: 0
D10: 0
D11: 0
D12: 0
D13: 0
D14: 0
D15: 0
D16: 0
D17: 0
D18: 0
C19: 合計金額 | D19: =SUM(D7:D18) -> 0
A20: ※不要な行は削除すること
A21: ※支払先が個人の場合は個人名を企業名欄に記載し、金額欄は源泉税込みの金額を記載すること
A22: ※見積書へ見積No.をまたは請求書へ請求No.を記載すること
A24: ※採用企業合計＋振込手数料＋予備費＝事業費合計になることを確認下さい。
A27: =IF(A2="見積企業一覧表","見積№",IF(A2="請求企業一覧表","請求№","")) -> 見積№ | B27: 振込口座名義 | C27: 支払銀行・支店名 | D27: 口座番号 | E27: 振込手数料
D28: （普・当）
D29: （普・当）
D30: （普・当）
D31: （普・当）
D32: （普・当）
D33: （普・当）
D34: （普・当）
D35: 合計金額 | E35: =SUM(E28:E34) -> 0
A36: ※不要な行は削除すること
