Workbook

Sheet 主事業出欠表
B2: 事 業 等 | C2: 新年総会 | D2: ２０２６年度 新年交流会 | E2: 第４２回郷土かるた大会 | F2: ２月定例会 | G2: 拡大アワー | H2: ３月定例会 | I2: 地域アワー | J2: 新入会員バッチ授与式 | K2: 石川ブロック野球大会 | L2: ４月４LOM合同定例会 | M2: 第３８回わんぱく相撲加賀場所 | N2: ５月定例会 | O2: ６月定例会 | P2: 第２９回わんぱく相撲石川大会 | Q2: 第 回じゃがいもゴルフコンペ | R2: 地区フォーラムin | S2: 地区野球大会 | T2: JCIASPAC | U2: 石川コンファレンスＩＮ | V2: 7月定例会及び臨時総会 | W2: サマーコンファレンス | X2: 人財育成事業 | Y2: ８月定例会 | Z2: ９月3団体合同定例会 | AA2: わんぱく相撲全国女子大会 | AB2: 地域活性化事業 | AC2: 全国大会 大会 | AD2: １０月定例会及び臨時総会 | AE2: 第 回じゃがいもゴルフ大会 | AF2: １１月定例会 | AG2: 卒業式 | AH2: クリスマス家族交流会 | AI2: 12月定例会及び臨時総会
B3: 日 付 | E3: 46061 | F3: 46071
B4: メンバー数 | C4: 48 | D4: 48 | E4: 51 | F4: 51 | G4: 51 | H4: 51 | I4: 51 | J4: 51 | K4: 51 | L4: 51 | M4: 51 | N4: 51 | O4: 51 | P4: 51 | Q4: 51 | R4: 51 | S4: 51 | T4: 51 | U4: 51 | V4: 51 | W4: 51 | X4: 51 | Y4: 51 | Z4: 51 | AA4: 51 | AB4: 51 | AC4: 51 | AD4: 51 | AE4: 51 | AF4: 51 | AG4: 51 | AH4: 51 | AI4: 51
B5: 出席者（名） | C5: =COUNTIF(C7:C115,"○") -> 0 | D5: =COUNTIF(D7:D115,"○") -> 0 | E5: =COUNTIF(E7:E115,"○") -> 0 | F5: =COUNTIF(F7:F115,"○") -> 0 | G5: =COUNTIF(G7:G115,"○") -> 0 | H5: =COUNTIF(H7:H115,"○") -> 0 | I5: =COUNTIF(I7:I115,"○") -> 0 | J5: =COUNTIF(J7:J115,"○") -> 0 | ... AI5: =COUNTIF(AI7:AI115,"○") -> 0
B6: 出席率（％） | C6: =SUM(C5)/C4 -> 0.0% | D6: =SUM(D5)/D4 -> 0.0% | E6: =SUM(E5)/E4 -> 0.0% | F6: =SUM(F5)/F4 -> 0.0% | G6: =SUM(G5)/G4 -> 0.0% | H6: =SUM(H5)/H4 -> 0.0% | I6: =SUM(I5)/I4 -> 0.0% | J6: =SUM(J5)/J4 -> 0.0% | ... S6: =SUM(S5)/S4 -> 0.0% | T6: 0.111 | U6: =SUM(U5)/U4 -> 0.0% | V6: =SUM(V5)/V4 -> 0.0% | W6: =SUM(W5)/W4 -> 0.0% | X6: =SUM(X5)/X4 -> 0.0% | Y6: =SUM(Y5)/Y4 -> 0.0% | Z6: =SUM(Z5)/Z4 -> 0.0% | AA6: =SUM(AA5)/AA4 -> 0.0% | AB6: =SUM(AB5)/AB4 -> 0.0% | ... AI6: =SUM(AI5)/AI4 -> 0.0%
A7: 正副・直前・顧問・監事 | B7: 岡田 洋介
B8: 島 大助
B9: 矢田郷 和敬
B10: 吉田 洸市
B11: 吉田 翔馬
B12: 今井 拓哉
B13: 前田 拓真
B14: 岡澤 拓弥
B15: 中谷 一世
B21: 出席率 | C21: =COUNTIF(C7:C20,"○") -> 0/9 | D21: =COUNTIF(D7:D20,"○") -> 0/9 | E21: =COUNTIF(E7:E20,"○") -> 0/9 | F21: =COUNTIF(F7:F20,"○") -> 0/9 | G21: =COUNTIF(G7:G20,"○") -> 0/9 | H21: =COUNTIF(H7:H20,"○") -> 0/9 | I21: =COUNTIF(I7:I20,"○") -> 0/9 | J21: =COUNTIF(J7:J20,"○") -> 0/9 | ... AI21: =COUNTIF(AI7:AI20,"○") -> 0/9
A22: 事務局 | B22: 中川 恭甫
B23: 川根 駿
B24: 石上 紗理香
B25: 小嶋 裕子
B26: 早崎 峻徳
B27: 矢敷 卓朗
B33: 委員会出席率 | C33: =COUNTIF(C22:C32,"○") -> 0/6 | D33: =COUNTIF(D22:D32,"○") -> 0/6 | E33: =COUNTIF(E22:E32,"○") -> 0/6 | F33: =COUNTIF(F22:F32,"○") -> 0/6 | G33: =COUNTIF(G22:G32,"○") -> 0/6 | H33: =COUNTIF(H22:H32,"○") -> 0/6 | I33: =COUNTIF(I22:I32,"○") -> 0/6 | J33: =COUNTIF(J22:J32,"○") -> 0/6 | ... AI33: =COUNTIF(AI22:AI32,"○") -> 0/6
A34: まちづくり委員会 | B34: 池端 秀人
B35: 西谷 昭彦
B36: 衛藤 友也
B37: 大藏 竜也
B38: 加端 大樹
B39: 野崎 大
B40: 橋本 彩可
B41: 森元 瑛
B47: 委員会出席率 | C47: =COUNTIF(C34:C46,"○") -> 0/8 | D47: =COUNTIF(D34:D46,"○") -> 0/8 | E47: =COUNTIF(E34:E46,"○") -> 0/8 | F47: =COUNTIF(F34:F46,"○") -> 0/8 | G47: =COUNTIF(G34:G46,"○") -> 0/8 | H47: =COUNTIF(H34:H46,"○") -> 0/8 | I47: =COUNTIF(I34:I46,"○") -> 0/8 | J47: =COUNTIF(J34:J46,"○") -> 0/8 | ... AI47: =COUNTIF(AI34:AI46,"○") -> 0/8
A48: ひとづくり委員会 | B48: 曽根 詩乃
B49: 金井 大和
B50: 北村 翔太
B51: 治下 祐樹
B52: 下内 貴人
B53: 中村 正隆
B54: 福岡 善行
B55: 守岡 佑
B56: 西 利騎
...

Sheet 定例会・委員会
C3: 定例会 | O3: 委員会 | AB3: 定例会 | AN3: 委員会 | BA3: 定例会 | BM3: 委員会
C4: ① | D4: ② | E4: ③ | F4: ④ | G4: ⑤ | H4: ⑥ | I4: ⑦ | J4: ⑧ | K4: ⑨ | L4: ⑩ | M4: ⑩ | N4: ⑫ | O4: ① | P4: ② | Q4: ③ | R4: ④ | S4: ⑤ | T4: ⑥ | U4: ⑦ | V4: ⑧ | W4: ⑨ | X4: ⑩ | Y4: ⑪ | AB4: ① | AC4: ② | AD4: ③ | AE4: ④ | AF4: ⑤ | AG4: ⑥ | AH4: ⑦ | AI4: ⑧ | AJ4: ⑨ | AK4: ⑩ | AL4: ⑪ | AM4: ⑫ | AN4: ① | AO4: ② | AP4: ③ | AQ4: ④ | AR4: ⑤ | AS4: ⑥ | AT4: ⑦ | AU4: ⑧ | AV4: ⑨ | AW4: ⑩ | AX4: ⑪ | BA4: ① | BB4: ② | BC4: ③ | BD4: ④ | BE4: ⑤ | BF4: ⑥ | BG4: ⑦ | BH4: ⑧ | BI4: ⑨ | BJ4: ⑩ | BK4: ⑪ | BL4: ⑫ | BM4: ① | BN4: ② | BO4: ③ | BP4: ④ | BQ4: ⑤ | BR4: ⑥ | BS4: ⑦ | BT4: ⑧ | BU4: ⑨ | BV4: ⑩ | BW4: ⑪
A5: 正副・直前・顧問・監事 | B5: 岡田 洋介 | Z5: まちづくり委員会 | AA5: 池端 秀人 | AN5: × | AO5: ○ | AP5: ○ | AQ5: ○ | AY5: 加賀絆委員会 | AZ5: 角出 芳樹 | BM5: ○ | BN5: ○ | BO5: ○ | BP5: ○
B6: 島 大助 | AA6: 西谷 昭彦 | AN6: ○ | AO6: ○ | AP6: ○ | AQ6: ○ | AZ6: 西戸 大樹 | BM6: ○ | BN6: ○ | BO6: ○ | BP6: ○
B7: 矢田郷 和敬 | AA7: 衛藤 友也 | AN7: ○ | AO7: × | AP7: × | AQ7: × | AZ7: 池越 眞平 | BM7: × | BN7: × | BO7: × | BP7: ×
B8: 吉田 洸市 | AA8: 大藏 竜也 | AN8: ○ | AO8: × | AP8: × | AQ8: ○ | AZ8: 喜多 絵里香 | BM8: ○ | BN8: ○ | BO8: ○ | BP8: ○
B9: 吉田 翔馬 | AA9: 加端 大樹 | AN9: ○ | AO9: × | AP9: ○ | AQ9: × | AZ9: 西出 泰伽 | BM9: × | BN9: × | BO9: × | BP9: ×
B10: 今井 拓哉 | AA10: 野崎 大 | AN10: × | AO10: × | AP10: ○ | AQ10: ○ | AZ10: 西山 峻史 | BM10: × | BN10: ○ | BO10: × | BP10: ×
B11: 前田 拓真 | AA11: 橋本 彩可 | AN11: ○ | AO11: × | AP11: ○ | AQ11: ○
B12: 岡澤 拓弥 | AA12: 森元 瑛 | AN12: × | AO12: × | AP12: ○ | AQ12: ×
B13: 中谷 一世
Z16: 8 | AY16: 6
Z17: ひとづくり委員会 | AA17: 曽根 詩乃 | AN17: ○ | AO17: ○ | AP17: ○ | AQ17: ○ | AY17: 財務・例会委員会 | AZ17: 奥村 航大 | BM17: ○ | BN17: ○ | BO17: ○ | BP17: ○
AA18: 金井 大和 | AN18: ○ | AO18: ○ | AP18: ○ | AQ18: ○ | AZ18: 竹野 有希 | BM18: ○ | BN18: ○ | BO18: ○ | BP18: ○
AA19: 北村 翔太 | AN19: ○ | AO19: ○ | AP19: × | AQ19: ○ | AZ19: 田中 太基 | BM19: × | BN19: ○ | BO19: ○ | BP19: ○
AA20: 治下 祐樹 | AN20: × | AO20: × | AP20: × | AQ20: × | AZ20: 西田 匠吾 | BM20: × | BN20: × | BO20: × | BP20: ×
AA21: 下内 貴人 | AN21: ○ | AO21: ○ | AP21: ○ | AQ21: × | AZ21: 西出 揮一郎 | BM21: × | BN21: × | BO21: ○ | BP21: ×
AA22: 中村 正隆 | AN22: ○ | AO22: ○ | AP22: × | AQ22: × | AZ22: 山﨑 翔己 | BM22: ○ | BN22: ？ | BO22: × | BP22: ○
A23: 9 | AA23: 福岡 善行 | AN23: ○ | AO23: ○ | AP23: ○ | AQ23: ○
A24: 事務局 | B24: 中川 恭甫 | O24: ○ | P24: ○ | Q24: ○ | R24: ○ | AA24: 守岡 佑 | AN24: ○ | AO24: × | AP24: ○ | AQ24: ○
B25: 川根 駿 | O25: ○ | P25: × | Q25: ○ | R25: ○ | AA25: 西 利騎 | AO25: ○ | AP25: ○ | AQ25: ×
B26: 石上 紗理香 | O26: × | P26: ○ | Q26: ○ | R26: × | AA26: 平田 拓巳 | AO26: ○ | AP26: × | AQ26: ○
B27: 小嶋 裕子 | O27: ○ | P27: × | Q27: ○ | R27: × | AA27: 山田 拓 | AP27: ○ | AQ27: ×
B28: 早崎 峻徳 | O28: ○ | P28: ○ | Q28: ○ | R28: × | AA28: 尾花 佑 | AP28: ○ | AQ28: ○
B29: 矢敷 卓朗 | O29: ○ | P29: ○ | Q29: ○ | R29: × | Z29: 8 | AA29: 瑓 貴大 | AP29: × | AQ29: ○ | AY29: 6
Z30: 会員開発委員会 | AA30: 藤澤 祐希 | AN30: ○ | AO30: ○ | AP30: ○ | AQ30: ○ | AY30: オブザーバー
AA31: 藤懿 仰 | AN31: ○ | AO31: ○ | AP31: ○ | AQ31: ○
AA32: 河西 紀明 | AN32: ○ | AO32: ○ | AP32: × | AQ32: ×
AA33: 東野 隼太 | AN33: × | AO33: × | AP33: × | AQ33: ×
AA34: 山口 銀斗 | AN34: ○ | AO34: × | AP34: × | AQ34: ×
AA35: 寺前 泰生 | AO35: ？ | AP35: × | AQ35: ×
A43: 6 | Z43: 5

Sheet 理事会
A1: ２０２６年度 理事会出欠状況
B2: １月 | C2: ２月 | D2: ３月 | E2: ４月 | F2: ５月 | G2: ６月 | H2: ７月 | I2: ８月 | J2: ９月 | K2: １０月 | L2: １１月 | M2: １２月 | N2: 出欠率(％)
A3: 岡田 洋介 | B3: ○ | C3: × | D3: ○ | N3: =COUNTIF(B3:M3,"○")/12 -> 17%
A4: 島 大助 | B4: ○ | C4: ○ | D4: × | N4: =COUNTIF(B4:M4,"○")/12 -> 17%
A5: 矢田郷 和敬 | B5: ○ | C5: ○ | D5: ○ | N5: =COUNTIF(B5:M5,"○")/12 -> 25%
A6: 吉田 洸市 | B6: ○ | C6: × | D6: ○ | N6: =COUNTIF(B6:M6,"○")/12 -> 17%
A7: 吉田 翔馬 | B7: ○ | C7: ○ | D7: ○ | N7: =COUNTIF(B7:M7,"○")/12 -> 25%
A8: 今井 拓哉 | B8: ○ | C8: ○ | D8: ○ | N8: =COUNTIF(B8:M8,"○")/12 -> 25%
A9: 前田 拓真 | B9: ○ | C9: ○ | D9: ○ | N9: =COUNTIF(B9:M9,"○")/12 -> 25%
A10: 岡澤 拓弥 | B10: ○ | C10: ○ | D10: ○ | N10: =COUNTIF(B10:M10,"○")/12 -> 25%
A11: 中谷 一世 | B11: ○ | C11: ○ | D11: ○ | N11: =COUNTIF(B11:M11,"○")/12 -> 25%
A12: 池端 秀人 | B12: ○ | C12: × | D12: × | N12: =COUNTIF(B12:M12,"○")/12 -> 8%
A13: 曽根 詩乃 | B13: ○ | C13: ○ | D13: ○ | N13: =COUNTIF(B13:M13,"○")/12 -> 25%
A14: 藤澤 祐希 | B14: ○ | C14: ○ | D14: ○ | N14: =COUNTIF(B14:M14,"○")/12 -> 25%
... A16: 奥村 航大 | B16: ○ | C16: ○ | D16: ○ | N16: =COUNTIF(B16:M16,"○")/12 -> 25%
A18: ｵﾌﾞｻﾞｰﾊﾞｰ
B19: １月 | C19: ２月 | D19: ３月 | E19: ４月 | F19: ５月 | G19: ６月 | H19: ７月 | I19: ８月 | J19: ９月 | K19: １０月 | L19: １１月 | M19: １２月 | N19: 出欠率(％)
A20: 川根 駿 | B20: ○ | C20: ○ | D20: ○ | N20: =COUNTIF(B20:M20,"○")/12 -> 25%
A21: 西谷 昭彦 | B21: ○ | C21: ○ | N21: =COUNTIF(B21:M21,"○")/12 -> 17%
A22: 藤懿 仰 | B22: ○ | C22: ○ | D22: ○ | N22: =COUNTIF(B22:M22,"○")/12 -> 25%
A23: 西戸 大樹 | B23: ○ | C23: ○ | D23: ○ | N23: =COUNTIF(B23:M23,"○")/12 -> 25%
A24: 竹野 有希 | B24: ○ | C24: ○ | N24: =COUNTIF(B24:M24,"○")/12 -> 17%
A25: 金井 大和 | C25: ○ | D25: ○ | N25: =COUNTIF(B25:M25,"○")/12 -> 17%
N26: =COUNTIF(B26:M26,"○")/12 -> 0%
N27: =COUNTIF(B27:M27,"○")/12 -> 0%
N28: =COUNTIF(B28:M28,"○")/12 -> 0%
N29: =COUNTIF(B29:M29,"○")/12 -> 0%
N30: =COUNTIF(B30:M30,"○")/12 -> 0%
N31: =COUNTIF(B31:M31,"○")/12 -> 0%

Sheet 出欠個人別割合表
C1: 理事会 | D1: 定例会 | E1: 委員会 | H1: 理事会 | I1: 定例会 | J1: 委員会 | M1: 理事会 | N1: 定例会 | O1: 委員会
A2: 正副・直前・顧問・監事 | B2: 岡田 洋介 | C2: =COUNTIF('理事会'!B3:M3,"○") -> 2/12 | D2: =COUNTIF('定例会・委員会'!C5:N5,"○") -> 0/12 | F2: まちづくり委員会 | G2: 池端 秀人 | H2: =COUNTIF('理事会'!B12:M12,"○") -> 1/12 | I2: =COUNTIF('定例会・委員会'!AB5:AM5,"○") -> 0/12 | J2: =COUNTIF('定例会・委員会'!AN5:AX5,"○") -> 3/11 | K2: 加賀絆委員会 | L2: 角出 芳樹 | M2: =COUNTIF('理事会'!B15:N15,"○") -> 3/12 | N2: =COUNTIF('定例会・委員会'!BA5:BL5,"○") -> 0/12 | O2: =COUNTIF('定例会・委員会'!BM5:BW5,"○") -> 4/11
B3: 島 大助 | C3: =COUNTIF('理事会'!B4:M4,"○") -> 2/12 | D3: =COUNTIF('定例会・委員会'!C6:N6,"○") -> 0/12 | G3: 西谷 昭彦 | H3: =COUNTIF('理事会'!B21:M21,"○") -> 2/12 | I3: =COUNTIF('定例会・委員会'!AB6:AM6,"○") -> 0/12 | J3: =COUNTIF('定例会・委員会'!AN6:AX6,"○") -> 4/11 | L3: 西戸 大樹 | M3: =COUNTIF('理事会'!B23:N23,"○") -> 3/12 | N3: =COUNTIF('定例会・委員会'!BA6:BL6,"○") -> 0/12 | O3: =COUNTIF('定例会・委員会'!BM6:BW6,"○") -> 4/11
B4: 矢田郷 和敬 | C4: =COUNTIF('理事会'!B5:M5,"○") -> 3/12 | D4: =COUNTIF('定例会・委員会'!C7:N7,"○") -> 0/12 | G4: 衛藤 友也 | I4: =COUNTIF('定例会・委員会'!AB7:AM7,"○") -> 0/12 | J4: =COUNTIF('定例会・委員会'!AN7:AX7,"○") -> 1/11 | L4: 池越 眞平 | N4: =COUNTIF('定例会・委員会'!BA7:BL7,"○") -> 0/12 | O4: =COUNTIF('定例会・委員会'!BM7:BW7,"○") -> 0/11
B5: 吉田 洸市 | C5: =COUNTIF('理事会'!B6:M6,"○") -> 2/12 | D5: =COUNTIF('定例会・委員会'!C8:N8,"○") -> 0/12 | G5: 大藏 竜也 | I5: =COUNTIF('定例会・委員会'!AB8:AM8,"○") -> 0/12 | J5: =COUNTIF('定例会・委員会'!AN8:AX8,"○") -> 2/11 | L5: 喜多 絵里香 | N5: =COUNTIF('定例会・委員会'!BA8:BL8,"○") -> 0/9 | O5: =COUNTIF('定例会・委員会'!BM8:BW8,"○") -> 4/9
B6: 吉田 翔馬 | C6: =COUNTIF('理事会'!B7:M7,"○") -> 3/12 | D6: =COUNTIF('定例会・委員会'!C9:N9,"○") -> 0/12 | G6: 加端 大樹 | I6: =COUNTIF('定例会・委員会'!AB9:AM9,"○") -> 0/12 | J6: =COUNTIF('定例会・委員会'!AN9:AX9,"○") -> 2/11 | L6: 西出 泰伽 | N6: =COUNTIF('定例会・委員会'!BA9:BL9,"○") -> 0/9 | O6: =COUNTIF('定例会・委員会'!BM9:BW9,"○") -> 0/9
B7: 今井 拓哉 | C7: =COUNTIF('理事会'!B8:M8,"○") -> 3/12 | D7: =COUNTIF('定例会・委員会'!C10:N10,"○") -> 0/12 | G7: 野崎 大 | I7: =COUNTIF('定例会・委員会'!AB10:AM10,"○") -> 0/12 | J7: =COUNTIF('定例会・委員会'!AN10:AX10,"○") -> 2/11 | L7: 西山 峻史 | N7: =COUNTIF('定例会・委員会'!BA10:BL10,"○") -> 0/12 | O7: =COUNTIF('定例会・委員会'!BM10:BW10,"○") -> 1/11
B8: 前田 拓真 | C8: =COUNTIF('理事会'!B9:M9,"○") -> 3/12 | D8: =COUNTIF('定例会・委員会'!C11:N11,"○") -> 0/12 | G8: 橋本 彩可 | I8: =COUNTIF('定例会・委員会'!AB11:AM11,"○") -> 0/12 | J8: =COUNTIF('定例会・委員会'!AN11:AX11,"○") -> 3/11 | N8: =COUNTIF('定例会・委員会'!BA11:BL11,"○") -> 0/12 | O8: =COUNTIF('定例会・委員会'!BM11:BW11,"○") -> 0/11
B9: 岡澤 拓弥 | C9: =COUNTIF('理事会'!B10:M10,"○") -> 3/12 | D9: =COUNTIF('定例会・委員会'!C12:N12,"○") -> 0/12 | G9: 森元 瑛 | I9: =COUNTIF('定例会・委員会'!AB12:AM12,"○") -> 0/12 | J9: =COUNTIF('定例会・委員会'!AN12:AX12,"○") -> 1/11 | N9: =COUNTIF('定例会・委員会'!BA12:BL12,"○") -> 0/12 | O9: =COUNTIF('定例会・委員会'!BM12:BW12,"○") -> 0/11
B10: 中谷 一世 | C10: =COUNTIF('理事会'!B11:M11,"○") -> 3/12 | D10: =COUNTIF('定例会・委員会'!C13:N13,"○") -> 0/12
F14: ひとづくり委員会 | G14: 曽根 詩乃 | H14: =COUNTIF('理事会'!B13:M13,"○") -> 3/12 | I14: =COUNTIF('定例会・委員会'!AB17:AM17,"○") -> 0/12 | J14: =COUNTIF('定例会・委員会'!AN17:AX17,"○") -> 4/11 | K14: 財務・例会委員会 | L14: 奥村 航大 | M14: =COUNTIF('理事会'!B16:N16,"○") -> 3/12 | N14: =COUNTIF('定例会・委員会'!BA17:BL17,"○") -> 0/12 | O14: =COUNTIF('定例会・委員会'!BM17:BW17,"○") -> 4/11
G15: 金井 大和 | H15: =COUNTIF('理事会'!B25:M25,"○") -> 2/12 | I15: =COUNTIF('定例会・委員会'!AB18:AM18,"○") -> 0/12 | J15: =COUNTIF('定例会・委員会'!AN18:AX18,"○") -> 4/11 | L15: 竹野 有希 | M15: =COUNTIF('理事会'!B24:N24,"○") -> 2/12 | N15: =COUNTIF('定例会・委員会'!BA18:BL18,"○") -> 0/12 | O15: =COUNTIF('定例会・委員会'!BM18:BW18,"○") -> 4/11
G16: 北村 翔太 | I16: =COUNTIF('定例会・委員会'!AB19:AM19,"○") -> 0/12 | J16: =COUNTIF('定例会・委員会'!AN19:AX19,"○") -> 3/11 | L16: 田中 太基 | N16: =COUNTIF('定例会・委員会'!BA19:BL19,"○") -> 0/12 | O16: =COUNTIF('定例会・委員会'!BM19:BW19,"○") -> 3/11
G17: 治下 祐樹 | I17: =COUNTIF('定例会・委員会'!AB20:AM20,"○") -> 0/12 | J17: =COUNTIF('定例会・委員会'!AN20:AX20,"○") -> 0/11 | L17: 西田 匠吾 | N17: =COUNTIF('定例会・委員会'!BA20:BL20,"○") -> 0/12 | O17: =COUNTIF('定例会・委員会'!BM20:BW20,"○") -> 0/11
G18: 下内 貴人 | I18: =COUNTIF('定例会・委員会'!AB21:AM21,"○") -> 0/12 | J18: =COUNTIF('定例会・委員会'!AN21:AX21,"○") -> 3/11 | L18: 西出 揮一郎 | N18: =COUNTIF('定例会・委員会'!BA21:BL21,"○") -> 0/12 | O18: =COUNTIF('定例会・委員会'!BM21:BW21,"○") -> 1/11
G19: 中村 正隆 | I19: =COUNTIF('定例会・委員会'!AB22:AM22,"○") -> 0/12 | J19: =COUNTIF('定例会・委員会'!AN22:AX22,"○") -> 2/11 | L19: 山﨑 翔己 | N19: =COUNTIF('定例会・委員会'!BA22:BL22,"○") -> 0/12 | O19: =COUNTIF('定例会・委員会'!BM22:BW22,"○") -> 2/11
A20: 事務局 | B20: 中川 恭甫 | D20: =COUNTIF('定例会・委員会'!C24:N24,"○") -> 0/12 | E20: =COUNTIF('定例会・委員会'!O24:Y24,"○") -> 4/11 | G20: 福岡 善行 | I20: =COUNTIF('定例会・委員会'!AB23:AM23,"○") -> 0/12 | J20: =COUNTIF('定例会・委員会'!AN23:AX23,"○") -> 4/11
B21: 川根 駿 | C21: =COUNTIF('理事会'!B20:M20,"○") -> 3/12 | D21: =COUNTIF('定例会・委員会'!C25:N25,"○") -> 0/12 | E21: =COUNTIF('定例会・委員会'!O25:Y25,"○") -> 3/11 | G21: 守岡 佑 | I21: =COUNTIF('定例会・委員会'!AB24:AM24,"○") -> 0/12 | J21: =COUNTIF('定例会・委員会'!AN24:AX24,"○") -> 3/11
B22: 石上 紗理香 | D22: =COUNTIF('定例会・委員会'!C26:N26,"○") -> 0/12 | E22: =COUNTIF('定例会・委員会'!O26:Y26,"○") -> 2/11 | G22: 西 利騎
B23: 小嶋 裕子 | D23: =COUNTIF('定例会・委員会'!C27:N27,"○") -> 0/12 | E23: =COUNTIF('定例会・委員会'!O27:Y27,"○") -> 2/11 | G23: 平田 拓巳
B24: 早崎 峻徳 | D24: =COUNTIF('定例会・委員会'!C28:N28,"○") -> 0/12 | E24: =COUNTIF('定例会・委員会'!O28:Y28,"○") -> 3/11
B25: 矢敷 卓朗 | D25: =COUNTIF('定例会・委員会'!C29:N29,"○") -> 0/12 | E25: =COUNTIF('定例会・委員会'!O29:Y29,"○") -> 3/11
F26: 会員開発委員会 | G26: 藤澤 祐希 | H26: =COUNTIF('理事会'!B14:M14,"○") -> 3/12 | I26: =COUNTIF('定例会・委員会'!AB30:AM30,"○") -> 0/12 | J26: =COUNTIF('定例会・委員会'!AN30:AX30,"○") -> 4/11
G27: 藤懿 仰 | H27: =COUNTIF('理事会'!B22:M22,"○") -> 3/12 | I27: =COUNTIF('定例会・委員会'!AB31:AM31,"○") -> 0/12 | J27: =COUNTIF('定例会・委員会'!AN31:AX31,"○") -> 4/11
G28: 河西 紀明 | I28: =COUNTIF('定例会・委員会'!AB32:AM32,"○") -> 0/12 | J28: =COUNTIF('定例会・委員会'!AN32:AX32,"○") -> 2/11
G29: 東野 隼太 | I29: =COUNTIF('定例会・委員会'!AB33:AM33,"○") -> 0/12 | J29: =COUNTIF('定例会・委員会'!AN33:AX33,"○") -> 0/11
G30: 山口 銀斗 | I30: =COUNTIF('定例会・委員会'!AB34:AM34,"○") -> 0/12 | J30: =COUNTIF('定例会・委員会'!AN34:AX34,"○") -> 1/11
G31: 寺前 泰生
